Workbook

Sheet Master
A1: Classname | B1: Teacher | C1: Location | D1: AmountStudents | E1: Profit/Loss | F1: Turnover | G1: Supplement | H1: Expense Teacher | I1: Rent | J1: Duration of Class | K1: Turnover / student | L1: Average Age | M1: Day | N1: Classtime
A2: Modern 10+ Intermediate | B2: Iris Heising | C2: Hengelo | D2: 3 | E2: =(F2+G2)-(H2+I2) -> -40.398932 | F2: 9.97 | G2: 0 | H2: =IFERROR(VLOOKUP(B2, 'Kosten Docenten'!A:B, 2, FALSE), "")*J2 -> 35 | I2: =IFERROR(VLOOKUP(C2, 'Kosten Locatie'!A:B, 2, FALSE), "")*J2 -> 15.368932 | J2: 1 | K2: 3.32 | M2: Tuesday | N2: 0.75
A3: Heels 15+ Intermediate | B3: Isabel | C3: Hengelo | D3: 10 | E3: =(F3+G3)-(H3+I3) -> -37.941895 | F3: 45.87 | G3: 0 | H3: =IFERROR(VLOOKUP(B3, 'Kosten Docenten'!A:B, 2, FALSE), "")*J3 -> 68.442963 | I3: =IFERROR(VLOOKUP(C3, 'Kosten Locatie'!A:B, 2, FALSE), "")*J3 -> 15.368932 | J3: 1 | K3: 4.59 | M3: Wednesday | N3: 0.8125
A4: Commercial 15+ Beg (GoPlanet) | B4: Amarise | C4: Go Planet | D4: 5 | E4: =(F4+G4)-(H4+I4) -> -35.967128 | F4: 40.99 | G4: 0 | H4: =IFERROR(VLOOKUP(B4, 'Kosten Docenten'!A:B, 2, FALSE), "")*J4 -> 62.576667 | I4: =IFERROR(VLOOKUP(C4, 'Kosten Locatie'!A:B, 2, FALSE), "")*J4 -> 14.380462 | J4: 1 | K4: 8.2 | M4: Monday | N4: 0.77083333
A5: HipHop Foundations Beg | B5: Christiaan | C5: Hengelo | D5: 7 | E5: =(F5+G5)-(H5+I5) -> -28.192265 | F5: 36.65 | G5: 0 | H5: =IFERROR(VLOOKUP(B5, 'Kosten Docenten'!A:B, 2, FALSE), "")*J5 -> 49.473333 | I5: =IFERROR(VLOOKUP(C5, 'Kosten Locatie'!A:B, 2, FALSE), "")*J5 -> 15.368932 | J5: 1 | K5: 5.24 | M5: Monday | N5: 0.75
A6: Hatha Yoga | B6: Kris | C6: Hengelo | D6: 5 | E6: =(F6+G6)-(H6+I6) -> -25.731165 | F6: 18.48 | G6: 0 | H6: =IFERROR(VLOOKUP(B6, 'Kosten Docenten'!A:B, 2, FALSE), "")*J6 -> 25 | I6: =IFERROR(VLOOKUP(C6, 'Kosten Locatie'!A:B, 2, FALSE), "")*J6 -> 19.211165 | J6: 1.25 | K6: 3.7 | M6: Wednesday | N6: 0.83333333
A7: Battle Camp Elite (Team) | B7: Imaury | C7: Hengelo | D7: 7 | E7: =(F7+G7)-(H7+I7) -> -25.415751 | F7: 59.6 | G7: 23.92 | H7: =IFERROR(VLOOKUP(B7, 'Kosten Docenten'!A:B, 2, FALSE), "")*J7 -> 85.882353 | I7: =IFERROR(VLOOKUP(C7, 'Kosten Locatie'!A:B, 2, FALSE), "")*J7 -> 23.053398 | J7: 1.5 | K7: 8.51 | M7: Thursday | N7: 0.75
A8: BATTLE CAMP (Team) | B8: Imaury | C8: Hengelo | D8: 11 | E8: =(F8+G8)-(H8+I8) -> -22.765751 | F8: 60.42 | G8: 25.75 | H8: =IFERROR(VLOOKUP(B8, 'Kosten Docenten'!A:B, 2, FALSE), "")*J8 -> 85.882353 | I8: =IFERROR(VLOOKUP(C8, 'Kosten Locatie'!A:B, 2, FALSE), "")*J8 -> 23.053398 | J8: 1.5 | K8: 5.49 | M8: Thursday | N8: 0.8125
A9: Commercial Jazz 12+ int | B9: Isabel | C9: Hengelo | D9: 23 | E9: =(F9+G9)-(H9+I9) -> -21.531895 | F9: 62.28 | G9: 0 | H9: =IFERROR(VLOOKUP(B9, 'Kosten Docenten'!A:B, 2, FALSE), "")*J9 -> 68.442963 | I9: =IFERROR(VLOOKUP(C9, 'Kosten Locatie'!A:B, 2, FALSE), "")*J9 -> 15.368932 | J9: 1 | K9: 2.71 | M9: Wednesday | N9: 0.77083333
A10: A-Selectie Techniek | B10: Isabel | C10: Hengelo | D10: 17 | E10: =(F10+G10)-(H10+I10) -> -20.657843 | F10: 82.85 | G10: 22.21 | H10: =IFERROR(VLOOKUP(B10, 'Kosten Docenten'!A:B, 2, FALSE), "")*J10 -> 102.66444 | I10: =IFERROR(VLOOKUP(C10, 'Kosten Locatie'!A:B, 2, FALSE), "")*J10 -> 23.053398 | J10: 1.5 | K10: 4.87 | M10: Friday | N10: 0.78125
A11: Ballet adult beginners (GoPlanet) | B11: Amarise | C11: Go Planet | D11: 9 | E11: =(F11+G11)-(H11+I11) -> -17.467128 | F11: 59.49 | G11: 0 | H11: =IFERROR(VLOOKUP(B11, 'Kosten Docenten'!A:B, 2, FALSE), "")*J11 -> 62.576667 | I11: =IFERROR(VLOOKUP(C11, 'Kosten Locatie'!A:B, 2, FALSE), "")*J11 -> 14.380462 | J11: 1 | K11: 6.61 | M11: Monday | N11: 0.8125
A12: Tap 8+ Beginners | B12: May | C12: Hengelo | D12: 3 | E12: =(F12+G12)-(H12+I12) -> -16.038932 | F12: 14.33 | G12: 0 | H12: =IFERROR(VLOOKUP(B12, 'Kosten Docenten'!A:B, 2, FALSE), "")*J12 -> 15 | I12: =IFERROR(VLOOKUP(C12, 'Kosten Locatie'!A:B, 2, FALSE), "")*J12 -> 15.368932 | J12: 1 | K12: 4.78 | M12: Monday | N12: 0.70833333
A13: Ballet 13+ Beg (Enschede) | B13: Saskia | C13: Enschede | D13: 10 | E13: =(F13+G13)-(H13+I13) -> -13.051302 | F13: 61.89 | G13: 2.68 | H13: =IFERROR(VLOOKUP(B13, 'Kosten Docenten'!A:B, 2, FALSE), "")*J13 -> 55 | I13: =IFERROR(VLOOKUP(C13, 'Kosten Locatie'!A:B, 2, FALSE), "")*J13 -> 22.621302 | J13: 1 | K13: 6.19 | M13: Tuesday | N13: 0.77083333
... A159: K-Pop 12+ Open | B159: Kyra | C159: Hengelo | D159: 35 | E159: =(F159+G159)-(H159+I159) -> 230.21107 | F159: 265.58 | G159: 0 | H159: =IFERROR(VLOOKUP(B159, 'Kosten Docenten'!A:B, 2, FALSE), "")*J159 -> 20 | I159: =IFERROR(VLOOKUP(C159, 'Kosten Locatie'!A:B, 2, FALSE), "")*J159 -> 15.368932 | J159: 1 | K159: 7.59 | M159: Monday | N159: 0.79166667

Sheet Locatie Prestaties
A1: Locatie | B1: Gem. zaalhuur | C1: Gem. Winst/les | D1: Gem. groepsgrootte | E1: Totale opbrengst | F1: Totaal aantal leerlingen
A2: Haaksbergen | C2: =IFERROR(AVERAGEIF(Master!C:C, A2, Master!E:E), "") -> 50.235 | D2: =IFERROR(AVERAGEIF(Master!C:C, A2, Master!D:D), "") -> 10.5 | E2: =IFERROR(SUMIF(Master!C:C, A2, Master!E:E), "") -> 100.47 | F2: =IFERROR(SUMIF(Master!C:C, A2, Master!D:D), "") -> 21
A3: Bentelo | C3: =IFERROR(AVERAGEIF(Master!C:C, A3, Master!E:E), "") -> 52.508462 | D3: =IFERROR(AVERAGEIF(Master!C:C, A3, Master!D:D), "") -> 12 | E3: =IFERROR(SUMIF(Master!C:C, A3, Master!E:E), "") -> 52.508462 | F3: =IFERROR(SUMIF(Master!C:C, A3, Master!D:D), "") -> 12
A4: Slangenbeek | C4: =IFERROR(AVERAGEIF(Master!C:C, A4, Master!E:E), "") -> 95.23 | D4: =IFERROR(AVERAGEIF(Master!C:C, A4, Master!D:D), "") -> 15 | E4: =IFERROR(SUMIF(Master!C:C, A4, Master!E:E), "") -> 285.69 | F4: =IFERROR(SUMIF(Master!C:C, A4, Master!D:D), "") -> 45
A5: Hasseler Es | C5: =IFERROR(AVERAGEIF(Master!C:C, A5, Master!E:E), "") -> 132.27333 | D5: =IFERROR(AVERAGEIF(Master!C:C, A5, Master!D:D), "") -> 19 | E5: =IFERROR(SUMIF(Master!C:C, A5, Master!E:E), "") -> 396.82 | F5: =IFERROR(SUMIF(Master!C:C, A5, Master!D:D), "") -> 57
A6: Enschede | C6: =IFERROR(AVERAGEIF(Master!C:C, A6, Master!E:E), "") -> 66.538594 | D6: =IFERROR(AVERAGEIF(Master!C:C, A6, Master!D:D), "") -> 16 | E6: =IFERROR(SUMIF(Master!C:C, A6, Master!E:E), "") -> 1730.0034 | F6: =IFERROR(SUMIF(Master!C:C, A6, Master!D:D), "") -> 416
A7: Go Planet | C7: =IFERROR(AVERAGEIF(Master!C:C, A7, Master!E:E), "") -> 61.009094 | D7: =IFERROR(AVERAGEIF(Master!C:C, A7, Master!D:D), "") -> 14.55 | E7: =IFERROR(SUMIF(Master!C:C, A7, Master!E:E), "") -> 1220.1819 | F7: =IFERROR(SUMIF(Master!C:C, A7, Master!D:D), "") -> 291
A8: Hengelo | C8: =IFERROR(AVERAGEIF(Master!C:C, A8, Master!E:E), "") -> 60.50332 | D8: =IFERROR(AVERAGEIF(Master!C:C, A8, Master!D:D), "") -> 16.951456 | E8: =IFERROR(SUMIF(Master!C:C, A8, Master!E:E), "") -> 6231.842 | F8: =IFERROR(SUMIF(Master!C:C, A8, Master!D:D), "") -> 1746

Sheet Docenten Prestaties
A1: Docent | B1: Totale winst | C1: Winst per lesuur | D1: Aantal lesuren | F1: Docent | G1: Totale winst | I1: Docent | J1: Totale winst | K1: Winst per lesuur
A2: Kris | B2: =SUMIF(Master!B:B, A2, Master!E:E) -> -25.731165 | C2: =B2/D2 -> -25.731165 | D2: =COUNTIF(Master!B:B, A2) -> 1 | F2: {=SORT(A2:B999,2,TRUE())} -> Isabel | G2: -26.480291 | I2: {=SORT(A2:C999,3,TRUE())} -> Kris | J2: -25.731165 | K2: -25.731165
A3: Isabel | B3: =SUMIF(Master!B:B, A3, Master!E:E) -> -26.480291 | C3: =B3/D3 -> -4.4133819 | D3: =COUNTIF(Master!B:B, A3) -> 6 | F3: Kris | G3: -25.731165 | I3: May | J3: -16.038932 | K3: -16.038932
A4: May | B4: =SUMIF(Master!B:B, A4, Master!E:E) -> -16.038932 | C4: =B4/D4 -> -16.038932 | D4: =COUNTIF(Master!B:B, A4) -> 1 | F4: May | G4: -16.038932 | I4: Isabel | J4: -26.480291 | K4: -4.4133819
A5: Valeriia | B5: =SUMIF(Master!B:B, A5, Master!E:E) -> -7.0378641 | C5: =B5/D5 -> -3.518932 | D5: =COUNTIF(Master!B:B, A5) -> 2 | F5: Valeriia | G5: -7.0378641 | I5: Valeriia | J5: -7.0378641 | K5: -3.518932
A6: Hamiro | B6: =SUMIF(Master!B:B, A6, Master!E:E) -> -1.0367961 | C6: =B6/D6 -> -0.34559871 | D6: =COUNTIF(Master!B:B, A6) -> 3 | F6: Hamiro | G6: -1.0367961 | I6: Hamiro | J6: -1.0367961 | K6: -0.34559871
A7: Brechtje & Sophie | B7: =SUMIF(Master!B:B, A7, Master!E:E) -> 20.639538 | C7: =B7/D7 -> 20.639538 | D7: =COUNTIF(Master!B:B, A7) -> 1 | F7: Amarise | G7: 5.3986154 | I7: Amarise | J7: 5.3986154 | K7: 1.7995385
A8: Ruben | B8: =SUMIF(Master!B:B, A8, Master!E:E) -> 37.195437 | C8: =B8/D8 -> 12.398479 | D8: =COUNTIF(Master!B:B, A8) -> 3 | F8: Brechtje & Sophie | G8: 20.639538 | I8: Ruben | J8: 37.195437 | K8: 12.398479
A9: Eline | B9: =SUMIF(Master!B:B, A9, Master!E:E) -> 44.471068 | C9: =B9/D9 -> 44.471068 | D9: =COUNTIF(Master!B:B, A9) -> 1 | F9: Ruben | G9: 37.195437 | I9: Brechtje & Sophie | J9: 20.639538 | K9: 20.639538
A10: Brechtje | B10: =SUMIF(Master!B:B, A10, Master!E:E) -> 50.060606 | C10: =B10/D10 -> 25.030303 | D10: =COUNTIF(Master!B:B, A10) -> 2 | F10: Eline | G10: 44.471068 | I10: Christiaan | J10: 62.603204 | K10: 20.867735
A11: Rowdy | B11: =SUMIF(Master!B:B, A11, Master!E:E) -> 64.788698 | C11: =B11/D11 -> 64.788698 | D11: =COUNTIF(Master!B:B, A11) -> 1 | F11: Brechtje | G11: 50.060606 | I11: Brechtje | J11: 50.060606 | K11: 25.030303
A12: Floor | B12: =SUMIF(Master!B:B, A12, Master!E:E) -> 54.242136 | C12: =B12/D12 -> 27.121068 | D12: =COUNTIF(Master!B:B, A12) -> 2 | F12: Floor | G12: 54.242136 | I12: Floor | J12: 54.242136 | K12: 27.121068
A13: Amarise | B13: =SUMIF(Master!B:B, A13, Master!E:E) -> 5.3986154 | C13: =B13/D13 -> 1.7995385 | D13: =COUNTIF(Master!B:B, A13) -> 3 | F13: Christiaan | G13: 62.603204 | I13: Saskia | J13: 570.75427 | K13: 35.672142
A14: Christiaan | B14: =SUMIF(Master!B:B, A14, Master!E:E) -> 62.603204 | C14: =B14/D14 -> 20.867735 | D14: =COUNTIF(Master!B:B, A14) -> 3 | F14: Rowdy | G14: 64.788698 | I14: Iris Heising | J14: 300.82487 | K14: 42.974981
... A35: Mara | B35: =SUMIF(Master!B:B, A35, Master!E:E) -> 460.31748 | C35: =B35/D35 -> 76.719579 | D35: =COUNTIF(Master!B:B, A35) -> 6 | F35: Mara | G35: 460.31748 | I35: Tay & Dilara | J35: 186.34272 | K35: 93.171361
A36: Lotte | B36: =SUMIF(Master!B:B, A36, Master!E:E) -> 554.17219 | C36: =B36/D36 -> 92.362032 | D36: 6 | F36: Lotte | G36: 554.17219 | I36: Xena | J36: 579.46 | K36: 115.892
A37: Bengt | B37: =SUMIF(Master!B:B, A37, Master!E:E) -> 570.43349 | C37: =B37/D37 -> 63.381499 | D37: =COUNTIF(Master!B:B, A37) -> 9 | F37: Bengt | G37: 570.43349 | I37: Tay | J37: 250.4887 | K37: 125.24435
A38: Saskia | B38: =SUMIF(Master!B:B, A38, Master!E:E) -> 570.75427 | C38: =B38/D38 -> 35.672142 | D38: =COUNTIF(Master!B:B, A38) -> 16 | F38: Saskia | G38: 570.75427 | I38: Kyra | J38: 383.05167 | K38: 127.68389
A39: Xena | B39: =SUMIF(Master!B:B, A39, Master!E:E) -> 579.46 | C39: =B39/D39 -> 115.892 | D39: =COUNTIF(Master!B:B, A39) -> 5 | F39: Xena | G39: 579.46 | I39: Lara | J39: 459.8932 | K39: 153.29773
A40: Hani | B40: =SUMIF(Master!B:B, A40, Master!E:E) -> 724.46398 | C40: =B40/D40 -> 90.557998 | D40: =COUNTIF(Master!B:B, A40) -> 8 | F40: Hani | G40: 724.46398 | I40: Tay & Mirthe | J40: 320.2274 | K40: 160.1137
A41: Imaury | B41: =SUMIF(Master!B:B, A41, Master!E:E) -> 809.67612 | C41: =B41/D41 -> 73.60692 | D41: =COUNTIF(Master!B:B, A41) -> 11 | F41: Imaury | G41: 809.67612 | I41: Sophie | J41: 326.16214 | K41: 163.08107

Sheet Kosten Docenten
A1: Docent | B1: Totale kosten /uur | C1: Uurtarief | D1: lessen | E1: uur | F1: Reiskosten | G1: Reiskosten / les
A2: Indy | B2: =C2+G2 -> 10 | C2: 10 | D2: =COUNTIF(Master!B:B, A2) -> 0 | E2: =SUMIF(Master!B:B, A2, Master!J:J) -> 0
A3: Jolijn | B3: =C3+G3 -> 10 | C3: 10 | D3: =COUNTIF(Master!B:B, A3) -> 0 | E3: =SUMIF(Master!B:B, A3, Master!J:J) -> 0
A4: Brechtje | B4: =C4+G4 -> 10 | C4: 10 | D4: =COUNTIF(Master!B:B, A4) -> 2 | E4: =SUMIF(Master!B:B, A4, Master!J:J) -> 2
A5: Tay | B5: =C5+G5 -> 17.5 | C5: 17.5 | D5: =COUNTIF(Master!B:B, A5) -> 2 | E5: =SUMIF(Master!B:B, A5, Master!J:J) -> 2
A6: Dilara | B6: =C6+G6 -> 17.5 | C6: 17.5 | D6: =COUNTIF(Master!B:B, A6) -> 0 | E6: =SUMIF(Master!B:B, A6, Master!J:J) -> 0
A7: Kian | B7: =C7+G7 -> 15 | C7: 15 | D7: =COUNTIF(Master!B:B, A7) -> 0 | E7: =SUMIF(Master!B:B, A7, Master!J:J) -> 0
A8: May | B8: =C8+G8 -> 15 | C8: 15 | D8: =COUNTIF(Master!B:B, A8) -> 1 | E8: =SUMIF(Master!B:B, A8, Master!J:J) -> 1
A9: Kyra | B9: =C9+G9 -> 20 | C9: 20 | D9: =COUNTIF(Master!B:B, A9) -> 3 | E9: =SUMIF(Master!B:B, A9, Master!J:J) -> 3
A10: Eline | B10: =C10+G10 -> 20 | C10: 20 | D10: =COUNTIF(Master!B:B, A10) -> 1 | E10: =SUMIF(Master!B:B, A10, Master!J:J) -> 1
A11: Lara | B11: =C11+G11 -> 22.5 | C11: 22.5 | D11: =COUNTIF(Master!B:B, A11) -> 3 | E11: =SUMIF(Master!B:B, A11, Master!J:J) -> 3
A12: Isa | B12: =C12+G12 -> 38.715 | C12: 22.5 | D12: =COUNTIF(Master!B:B, A12) -> 4 | E12: =SUMIF(Master!B:B, A12, Master!J:J) -> 4 | F12: 64.86 | G12: =F12/E12 -> 16.215
A13: Floor | B13: =C13+G13 -> 30 | C13: 30 | D13: =COUNTIF(Master!B:B, A13) -> 2 | E13: =SUMIF(Master!B:B, A13, Master!J:J) -> 2
A14: Myrthe | B14: =C14+G14 -> 22.5 | C14: 22.5 | D14: =COUNTIF(Master!B:B, A14) -> 1 | E14: =SUMIF(Master!B:B, A14, Master!J:J) -> 1
A15: Anne | B15: =C15+G15 -> 22.5 | C15: 22.5 | D15: =COUNTIF(Master!B:B, A15) -> 2 | E15: =SUMIF(Master!B:B, A15, Master!J:J) -> 2
A16: Vera | B16: =C16+G16 -> 20 | C16: 20 | D16: =COUNTIF(Master!B:B, A16) -> 3 | E16: =SUMIF(Master!B:B, A16, Master!J:J) -> 3
A17: Lisanne | B17: =C17+G17 -> 20 | C17: 20 | D17: =COUNTIF(Master!B:B, A17) -> 4 | E17: =SUMIF(Master!B:B, A17, Master!J:J) -> 4
A18: Kris | B18: =C18+G18 -> 20 | C18: 20 | D18: =COUNTIF(Master!B:B, A18) -> 1 | E18: =SUMIF(Master!B:B, A18, Master!J:J) -> 1.25
A19: Guusje | B19: =C19+G19 -> 25 | C19: 25 | D19: =COUNTIF(Master!B:B, A19) -> 3 | E19: =SUMIF(Master!B:B, A19, Master!J:J) -> 3
A20: Mara | B20: =C20+G20 -> 30 | C20: 30 | D20: =COUNTIF(Master!B:B, A20) -> 6 | E20: =SUMIF(Master!B:B, A20, Master!J:J) -> 7
A21: Carmen | B21: =C21+G21 -> 26.25 | C21: 25 | D21: =COUNTIF(Master!B:B, A21) -> 4 | E21: =SUMIF(Master!B:B, A21, Master!J:J) -> 4 | F21: 5 | G21: =F21/E21 -> 1.25
A22: Sophie | B22: =C22+G22 -> 30 | C22: 30 | D22: =COUNTIF(Master!B:B, A22) -> 2 | E22: =SUMIF(Master!B:B, A22, Master!J:J) -> 2
A23: Iris Wilms | B23: =C23+G23 -> 30 | C23: 30 | D23: =COUNTIF(Master!B:B, A23) -> 5 | E23: =SUMIF(Master!B:B, A23, Master!J:J) -> 5
A24: Christiaan | B24: =C24+G24 -> 49.473333 | C24: 30 | D24: =COUNTIF(Master!B:B, A24) -> 3 | E24: =SUMIF(Master!B:B, A24, Master!J:J) -> 3 | F24: 58.42 | G24: =F24/E24 -> 19.473333
A25: Iris Heising | B25: =C25+G25 -> 35 | C25: 35 | D25: =COUNTIF(Master!B:B, A25) -> 7 | E25: =SUMIF(Master!B:B, A25, Master!J:J) -> 7
A26: Hamiro | B26: =C26+G26 -> 43.333333 | C26: 35 | D26: =COUNTIF(Master!B:B, A26) -> 3 | E26: =SUMIF(Master!B:B, A26, Master!J:J) -> 3 | F26: 25 | G26: =F26/E26 -> 8.3333333
A27: Rowdy | B27: =C27+G27 -> 35 | C27: 35 | D27: =COUNTIF(Master!B:B, A27) -> 1 | E27: =SUMIF(Master!B:B, A27, Master!J:J) -> 1
A28: Lotte | B28: =C28+G28 -> 48.333333 | C28: 35 | D28: =COUNTIF(Master!B:B, A28) -> 6 | E28: =SUMIF(Master!B:B, A28, Master!J:J) -> 6 | F28: 80 | G28: =F28/E28 -> 13.333333
A29: Bengt | B29: =C29+G29 -> 46.222222 | C29: 40 | D29: =COUNTIF(Master!B:B, A29) -> 9 | E29: =SUMIF(Master!B:B, A29, Master!J:J) -> 9 | F29: 56 | G29: =F29/E29 -> 6.2222222
A30: Samara | B30: =C30+G30 -> 35 | C30: 35 | D30: =COUNTIF(Master!B:B, A30) -> 0 | E30: =SUMIF(Master!B:B, A30, Master!J:J) -> 0
A31: Saskia | B31: =C31+G31 -> 55 | C31: 55 | D31: =COUNTIF(Master!B:B, A31) -> 16 | E31: =SUMIF(Master!B:B, A31, Master!J:J) -> 13.5
A32: Isabel | B32: =C32+G32 -> 68.442963 | C32: 45 | D32: =COUNTIF(Master!B:B, A32) -> 6 | E32: =SUMIF(Master!B:B, A32, Master!J:J) -> 6.75 | F32: =79.12*2 -> 158.24 | G32: =F32/E32 -> 23.442963
A33: Imaury | B33: =C33+G33 -> 57.254902 | C33: 50 | D33: =COUNTIF(Master!B:B, A33) -> 11 | E33: =SUMIF(Master!B:B, A33, Master!J:J) -> 12.75 | F33: 92.5 | G33: =F33/E33 -> 7.254902
A34: Jasmijn | B34: =C34+G34 -> 50 | C34: 50 | D34: =COUNTIF(Master!B:B, A34) -> 3 | E34: =SUMIF(Master!B:B, A34, Master!J:J) -> 3
A35: Marnix | B35: =C35+G35 -> 45 | C35: 45 | D35: =COUNTIF(Master!B:B, A35) -> 0 | E35: =SUMIF(Master!B:B, A35, Master!J:J) -> 0
A36: Ruben | B36: =C36+G36 -> 53.636364 | C36: 50 | D36: =COUNTIF(Master!B:B, A36) -> 3 | E36: =SUMIF(Master!B:B, A36, Master!J:J) -> 2.75 | F36: 10 | G36: =F36/E36 -> 3.6363636
A37: Bas | B37: =C37+G37 -> 25 | C37: 25 | D37: =COUNTIF(Master!B:B, A37) -> 6 | E37: =SUMIF(Master!B:B, A37, Master!J:J) -> 6.5
A38: Valeriia | B38: =C38+G38 -> 17.5 | C38: 17.5 | D38: =COUNTIF(Master!B:B, A38) -> 2 | E38: =SUMIF(Master!B:B, A38, Master!J:J) -> 2
A39: Merle | B39: =C39+G39 -> 10 | C39: 10 | D39: =COUNTIF(Master!B:B, A39) -> 2 | E39: =SUMIF(Master!B:B, A39, Master!J:J) -> 2
A40: Mirthe | B40: =C40+G40 -> 10 | C40: 10 | D40: =COUNTIF(Master!B:B, A40) -> 0 | E40: =SUMIF(Master!B:B, A40, Master!J:J) -> 0
...

Sheet Kosten Locatie
A1: Locatie | B1: Kosten / uur | C1: Aantal lessen | D1: Locatiehuur per maand
A2: Hengelo | B2: =(D2*12)/(C2*39) -> 15.368932 | C2: =COUNTIF(Master!C:C,A2) -> 103 | D2: =3844.25+1300.5 -> 5144.75
A3: Enschede | B3: =(D3*12)/(C3*39) -> 22.621302 | C3: =COUNTIF(Master!C:C,A3) -> 26 | D3: 1911.5
A4: Go Planet | B4: =(D4*12)/(C4*39) -> 14.380462 | C4: =COUNTIF(Master!C:C,A4) -> 20 | D4: 934.73
A5: Haaksbergen | B5: 17.5 | C5: =COUNTIF(Master!C:C,A5) -> 2
A6: Slangenbeek | B6: 19.05 | C6: =COUNTIF(Master!C:C,A6) -> 3
A7: Hasseler Es | B7: 19.05 | C7: =COUNTIF(Master!C:C,A7) -> 3
A8: Bentelo | B8: =(D8*12)/(C8*39) -> 18.461538 | C8: =COUNTIF(Master!C:C,A8) -> 1 | D8: 60
